Workbook

Sheet Planilha7
A1: ano | B1: 2026
E2: Ordem | F2: Não conformidade | G2: Frequência
A3: Rótulos de Linha | B3: Contagem de Detalhes_NC | E3: 1 | F3: Ausência de Placa de identificação / segurança | G3: 7
A4: Ausência de Etiqueta de calibração do medidor | B4: 3 | E4: 2 | F4: Ausência de Etiqueta de calibração do medidor | G4: 3
A5: Ausência de Placa de identificação / segurança | B5: 7 | E5: 3 | F5: Lacre da válvula de bloqueio a montante violado | G5: 3
A6: Cadeado oxidado impedindo a abertura da porta | B6: 1 | E6: 4 | F6: Portão da estação desafixado | G6: 3
A7: Entulho obstruindo o acesso | B7: 1 | E7: 5 | F7: PSV com etiqueta de calibração vencida | G7: 2
A8: Etiqueta de calibração com data incompleta | B8: 1 | E8: 6 | F8: Cadeado oxidado impedindo a abertura da porta | G8: 1
A9: Lacre da válvula de bloqueio a montante violado | B9: 3 | E9: 7 | F9: Entulho obstruindo o acesso | G9: 1
A10: Placa de identificação / egurança ilegível | B10: 1 | E10: 8 | F10: Etiqueta de calibração com data incompleta | G10: 1
A11: Placa de identificação / segurança ilegível | B11: 1 | E11: 9 | F11: Placa de identificação / egurança ilegível | G11: 1
A12: Portão da estação desafixado | B12: 3 | E12: 10 | F12: Placa de identificação / segurança ilegível | G12: 1
A13: PSV com etiqueta de calibração vencida | B13: 2 | E13: 11 | F13: PSV sem etiqueta de calibração | G13: 1
A14: PSV sem etiqueta de calibração | B14: 1 | E14: 12 | F14: Quadro de medidores com a base oxidada | G14: 1
A15: Quadro de medidores com a base oxidada | B15: 1 | E15: 13 | F15: Quadro de medidores com a porta oxidada | G15: 1
A16: Quadro de medidores com a porta oxidada | B16: 1 | E16: 14 | F16: Vazamento de gás | G16: 1
A17: Vazamento de gás | B17: 1
A18: Total Geral | B18: 27

Sheet Planilha5
A1: Data | B1: (Vários itens)
A3: Rótulos de Linha | B3: Contagem de ID_FISC
A4: Comercial | B4: 3
A5: ERP | B5: 1
A6: ETC | B6: 2
A7: GNV | B7: 2
A8: Industrial | B8: 5
A9: Residencial | B9: 3
A10: Total Geral | B10: 16

Sheet Fiscalizacoes
A1: ID_FISC | B1: Data | C1: Mes_relatorio | D1: Usuário | E1: Logradouro | F1: Endereco | G1: Numero | H1: Bairro | I1: Cidade | J1: Segmento | K1: COD_CR | L1: Mvaz | M1: Tipo_Medidor | N1: Calibracao | O1: Prox_Calib | P1: Func_ARPE | Q1: Func_Copergas | R1: Motorista | S1: Tipo_fisc
A2: 2024001 | B2: 45303 | C2: =TEXT(Fiscalizacoes[[#This Row],[Data]],"mm/aaaa") -> 01/2024 | D2: RESIDENCIAL CAMPO DE AVIAÇÃO - CONDOMINIO HANGAR - CR | E2: Rua | F2: Campo de Pouso | G2: 97 | H2: Maranguape | I2: Paulista | J2: Residencial | K2: CR 001 PAULISTA | L2: NA | M2: CR | P2: Argemiro / Marta | Q2: Gersom França Jr. | R2: Alex Rodrigues | S2: Ordinária
A3: 2024002 | B3: 45303 | C3: =TEXT(Fiscalizacoes[[#This Row],[Data]],"mm/aaaa") -> 01/2024 | D3: RESIDENCIAL CAMPO DE AVIAÇÃO - CONDOMINIO HANGAR - BLOCO A - TORRE 01 | E3: Rua | F3: Campo de Pouso | G3: 97 | H3: Maranguape | I3: Paulista | J3: Residencial | K3: CR 001 PAULISTA | L3: 05838-6 | M3: Diafragma | N3: 42155 | O3: 45808 | P3: Argemiro / Marta | Q3: Gersom França Jr. | R3: Alex Rodrigues | S3: Ordinária
A4: 2024003 | B4: 45303 | C4: =TEXT(Fiscalizacoes[[#This Row],[Data]],"mm/aaaa") -> 01/2024 | D4: RESIDENCIAL CAMPO DE AVIAÇÃO - CONDOMINIO HANGAR - BLOCO A - TORRE 02 | E4: Rua | F4: Campo de Pouso | G4: 97 | H4: Maranguape | I4: Paulista | J4: Residencial | K4: CR 001 PAULISTA | L4: 06019-4 | M4: Diafragma | N4: 42155 | O4: 45808 | P4: Argemiro / Marta | Q4: Gersom França Jr. | R4: Alex Rodrigues | S4: Ordinária
A5: 2024004 | B5: 45303 | C5: =TEXT(Fiscalizacoes[[#This Row],[Data]],"mm/aaaa") -> 01/2024 | D5: RESIDENCIAL CAMPO DE AVIAÇÃO - CONDOMINIO HANGAR - BLOCO B - TORRE 03 | E5: Rua | F5: Campo de Pouso | G5: 97 | H5: Maranguape | I5: Paulista | J5: Residencial | K5: CR 001 PAULISTA | L5: 18049-1 | M5: Diafragma | N5: 42674 | O5: 46326 | P5: Argemiro / Marta | Q5: Gersom França Jr. | R5: Alex Rodrigues | S5: Ordinária
A6: 2024005 | B6: 45303 | C6: =TEXT(Fiscalizacoes[[#This Row],[Data]],"mm/aaaa") -> 01/2024 | D6: RESIDENCIAL CAMPO DE AVIAÇÃO - CONDOMINIO HANGAR - BLOCO B - TORRE 04 | E6: Rua | F6: Campo de Pouso | G6: 97 | H6: Maranguape | I6: Paulista | J6: Residencial | K6: CR 001 PAULISTA | L6: 17613-3 | M6: Diafragma | N6: 42674 | O6: 46326 | P6: Argemiro / Marta | Q6: Gersom França Jr. | R6: Alex Rodrigues | S6: Ordinária
A7: 2024006 | B7: 45303 | C7: =TEXT(Fiscalizacoes[[#This Row],[Data]],"mm/aaaa") -> 01/2024 | D7: RESIDENCIAL CAMPO DE AVIAÇÃO - CONDOMINIO HANGAR - BLOCO C - TORRE 05 | E7: Rua | F7: Campo de Pouso | G7: 97 | H7: Maranguape | I7: Paulista | J7: Residencial | K7: CR 001 PAULISTA | L7: 29708-9 | M7: Diafragma | N7: 44742 | O7: 48395 | P7: Argemiro / Marta | Q7: Gersom França Jr. | R7: Alex Rodrigues | S7: Ordinária
A8: 2024007 | B8: 45303 | C8: =TEXT(Fiscalizacoes[[#This Row],[Data]],"mm/aaaa") -> 01/2024 | D8: RESIDENCIAL CAMPO DE AVIAÇÃO - CONDOMINIO HANGAR - BLOCO C - TORRE 06 | E8: Rua | F8: Campo de Pouso | G8: 97 | H8: Maranguape | I8: Paulista | J8: Residencial | K8: CR 001 PAULISTA | L8: 04955-7 | M8: Diafragma | N8: 42094 | O8: 45747 | P8: Argemiro / Marta | Q8: Gersom França Jr. | R8: Alex Rodrigues | S8: Ordinária
A9: 2024008 | B9: 45303 | C9: =TEXT(Fiscalizacoes[[#This Row],[Data]],"mm/aaaa") -> 01/2024 | D9: RESIDENCIAL CAMPO DE AVIAÇÃO - CONDOMINIO HANGAR - BLOCO D - TORRE 07 | E9: Rua | F9: Campo de Pouso | G9: 97 | H9: Maranguape | I9: Paulista | J9: Residencial | K9: CR 001 PAULISTA | L9: 06008-9 | M9: Diafragma | N9: 42155 | O9: 45808 | P9: Argemiro / Marta | Q9: Gersom França Jr. | R9: Alex Rodrigues | S9: Ordinária
A10: 2024009 | B10: 45303 | C10: =TEXT(Fiscalizacoes[[#This Row],[Data]],"mm/aaaa") -> 01/2024 | D10: RESIDENCIAL CAMPO DE AVIAÇÃO - CONDOMINIO HANGAR - BLOCO E - TORRE 08 | E10: Rua | F10: Campo de Pouso | G10: 97 | H10: Maranguape | I10: Paulista | J10: Residencial | K10: CR 001 PAULISTA | L10: 20676-8 | M10: Diafragma | N10: 42886 | O10: 46538 | P10: Argemiro / Marta | Q10: Gersom França Jr. | R10: Alex Rodrigues | S10: Ordinária
A11: 2024010 | B11: 45303 | C11: =TEXT(Fiscalizacoes[[#This Row],[Data]],"mm/aaaa") -> 01/2024 | D11: RESIDENCIAL CAMPO DE AVIAÇÃO - CONDOMINIO HANGAR - BLOCO E - TORRE 09 | E11: Rua | F11: Campo de Pouso | G11: 97 | H11: Maranguape | I11: Paulista | J11: Residencial | K11: CR 001 PAULISTA | L11: 06010-0 | M11: Diafragma | N11: 42155 | O11: 45808 | P11: Argemiro / Marta | Q11: Gersom França Jr. | R11: Alex Rodrigues | S11: Ordinária
A12: 2024011 | B12: 45303 | C12: =TEXT(Fiscalizacoes[[#This Row],[Data]],"mm/aaaa") -> 01/2024 | D12: RESIDENCIAL CAMPO DE AVIAÇÃO - CONDOMINIO HANGAR - BLOCO F - TORRE 10 | E12: Rua | F12: Campo de Pouso | G12: 97 | H12: Maranguape | I12: Paulista | J12: Residencial | K12: CR 001 PAULISTA | L12: 05932-3 | M12: Diafragma | N12: 42155 | O12: 45808 | P12: Argemiro / Marta | Q12: Gersom França Jr. | R12: Alex Rodrigues | S12: Ordinária
A13: 2024012 | B13: 45303 | C13: =TEXT(Fiscalizacoes[[#This Row],[Data]],"mm/aaaa") -> 01/2024 | D13: RESIDENCIAL CAMPO DE AVIAÇÃO - CONDOMINIO HANGAR - BLOCO F - TORRE 11 | E13: Rua | F13: Campo de Pouso | G13: 97 | H13: Maranguape | I13: Paulista | J13: Residencial | K13: CR 001 PAULISTA | L13: 17615-0 | M13: Diafragma | N13: 42674 | O13: 46326 | P13: Argemiro / Marta | Q13: Gersom França Jr. | R13: Alex Rodrigues | S13: Ordinária
A14: 2024013 | B14: 45303 | C14: =TEXT(Fiscalizacoes[[#This Row],[Data]],"mm/aaaa") -> 01/2024 | D14: RESIDENCIAL CAMPO DE AVIAÇÃO - CONDOMINIO HANGAR - BLOCO G - TORRE 12 | E14: Rua | F14: Campo de Pouso | G14: 97 | H14: Maranguape | I14: Paulista | J14: Residencial | K14: CR 001 PAULISTA | L14: 18149-8 | M14: Diafragma | N14: 42674 | O14: 46326 | P14: Argemiro / Marta | Q14: Gersom França Jr. | R14: Alex Rodrigues | S14: Ordinária
... A22: 2024021 | B22: 45303 | C22: =TEXT(Fiscalizacoes[[#This Row],[Data]],"mm/aaaa") -> 01/2024 | D22: RESIDENCIAL CAMPO DE AVIAÇÃO - CONDOMINIO HANGAR - BLOCO J - TORRE 19 | E22: Rua | F22: Campo de Pouso | G22: 97 | H22: Maranguape | I22: Paulista | J22: Residencial | K22: CR 001 PAULISTA | L22: 6530-7 | M22: Diafragma | N22: 42308 | O22: 45961 | P22: Argemiro / Marta | Q22: Gersom França Jr. | R22: Alex Rodrigues | S22: Ordinária
A23: 2024022 | B23: 45303 | C23: =TEXT(Fiscalizacoes[[#This Row],[Data]],"mm/aaaa") -> 01/2024 | D23: RESIDENCIAL CAMPO DE AVIAÇÃO - CONDOMINIO 14 BIS - CR | E23: Rua | F23: Campo de Pouso | G23: 193 | H23: Maranguape | I23: Paulista | J23: Residencial | K23: CR 002 PAULISTA | L23: NA | M23: CR | P23: Argemiro / Marta | Q23: Gersom França Jr. | R23: Alex Rodrigues | S23: Ordinária
A24: 2024023 | B24: 45303 | C24: =TEXT(Fiscalizacoes[[#This Row],[Data]],"mm/aaaa") -> 01/2024 | D24: RESIDENCIAL CAMPO DE AVIAÇÃO - CONDOMINIO 14 BIS - BLOCO A - TORRE 01 | E24: Rua | F24: Campo de Pouso | G24: 193 | H24: Maranguape | I24: Paulista | J24: Residencial | K24: CR 002 PAULISTA | L24: 29470-8 | M24: Diafragma | N24: 44742 | O24: 48395 | P24: Argemiro / Marta | Q24: Gersom França Jr. | R24: Alex Rodrigues | S24: Ordinária
A25: 2024024 | B25: 45303 | C25: =TEXT(Fiscalizacoes[[#This Row],[Data]],"mm/aaaa") -> 01/2024 | D25: RESIDENCIAL CAMPO DE AVIAÇÃO - CONDOMINIO 14 BIS - BLOCO A - TORRE 02 | E25: Rua | F25: Campo de Pouso | G25: 193 | H25: Maranguape | I25: Paulista | J25: Residencial | K25: CR 002 PAULISTA | L25: 20050-6 | M25: Diafragma | N25: 42886 | O25: 46538 | P25: Argemiro / Marta | Q25: Gersom França Jr. | R25: Alex Rodrigues | S25: Ordinária
A26: 2024025 | B26: 45303 | C26: =TEXT(Fiscalizacoes[[#This Row],[Data]],"mm/aaaa") -> 01/2024 | D26: RESIDENCIAL CAMPO DE AVIAÇÃO - CONDOMINIO 14 BIS - BLOCO B - TORRE 03 | E26: Rua | F26: Campo de Pouso | G26: 193 | H26: Maranguape | I26: Paulista | J26: Residencial | K26: CR 002 PAULISTA | L26: 22874-6 | M26: Diafragma | N26: 42035 | O26: 45688 | P26: Argemiro / Marta | Q26: Gersom França Jr. | R26: Alex Rodrigues | S26: Ordinária
A27: 2024026 | B27: 45303 | C27: =TEXT(Fiscalizacoes[[#This Row],[Data]],"mm/aaaa") -> 01/2024 | D27: RESIDENCIAL CAMPO DE AVIAÇÃO - CONDOMINIO 14 BIS - SALÃO DE FESTAS | E27: Rua | F27: Campo de Pouso | G27: 193 | H27: Maranguape | I27: Paulista | J27: Residencial | K27: CR 002 PAULISTA | M27: NV | P27: Argemiro / Marta | Q27: Gersom França Jr. | R27: Alex Rodrigues | S27: Ordinária
A28: 2024027 | B28: 45303 | C28: =TEXT(Fiscalizacoes[[#This Row],[Data]],"mm/aaaa") -> 01/2024 | D28: RESIDENCIAL CAMPO DE AVIAÇÃO - CONDOMINIO 14 BIS - BLOCO B - TORRE 04 | E28: Rua | F28: Campo de Pouso | G28: 193 | H28: Maranguape | I28: Paulista | J28: Residencial | K28: CR 002 PAULISTA | L28: 20888-4 | M28: Diafragma | N28: 42886 | O28: 46538 | P28: Argemiro / Marta | Q28: Gersom França Jr. | R28: Alex Rodrigues | S28: Ordinária
A29: 2024028 | B29: 45303 | C29: =TEXT(Fiscalizacoes[[#This Row],[Data]],"mm/aaaa") -> 01/2024 | D29: RESIDENCIAL CAMPO DE AVIAÇÃO - CONDOMINIO 14 BIS - BLOCO C - TORRE 05 | E29: Rua | F29: Campo de Pouso | G29: 193 | H29: Maranguape | I29: Paulista | J29: Residencial | K29: CR 002 PAULISTA | L29: 20355-6 | M29: Diafragma | N29: 42886 | O29: 46538 | P29: Argemiro / Marta | Q29: Gersom França Jr. | R29: Alex Rodrigues | S29: Ordinária
A30: 2024029 | B30: 45303 | C30: =TEXT(Fiscalizacoes[[#This Row],[Data]],"mm/aaaa") -> 01/2024 | D30: RESIDENCIAL CAMPO DE AVIAÇÃO - CONDOMINIO 14 BIS - BLOCO C - TORRE 06 | E30: Rua | F30: Campo de Pouso | G30: 193 | H30: Maranguape | I30: Paulista | J30: Residencial | K30: CR 002 PAULISTA | L30: 20770-8 | M30: Diafragma | N30: 42886 | O30: 46538 | P30: Argemiro / Marta | Q30: Gersom França Jr. | R30: Alex Rodrigues | S30: Ordinária
A31: 2024030 | B31: 45303 | C31: =TEXT(Fiscalizacoes[[#This Row],[Data]],"mm/aaaa") -> 01/2024 | D31: RESIDENCIAL CAMPO DE AVIAÇÃO - CONDOMINIO 14 BIS - BLOCO D - TORRE 07 | E31: Rua | F31: Campo de Pouso | G31: 193 | H31: Maranguape | I31: Paulista | J31: Residencial | K31: CR 002 PAULISTA | L31: 22218-6 | M31: Diafragma | N31: 43312 | O31: 46965 | P31: Argemiro / Marta | Q31: Gersom França Jr. | R31: Alex Rodrigues | S31: Ordinária
A32: 2024031 | B32: 45303 | C32: =TEXT(Fiscalizacoes[[#This Row],[Data]],"mm/aaaa") -> 01/2024 | D32: RESIDENCIAL CAMPO DE AVIAÇÃO - CONDOMINIO 14 BIS - BLOCO E - TORRE 08 | E32: Rua | F32: Campo de Pouso | G32: 193 | H32: Maranguape | I32: Paulista | J32: Residencial | K32: CR 002 PAULISTA | L32: 25588-2 | M32: Diafragma | N32: 43921 | O32: 47573 | P32: Argemiro / Marta | Q32: Gersom França Jr. | R32: Alex Rodrigues | S32: Ordinária
A33: 2024032 | B33: 45303 | C33: =TEXT(Fiscalizacoes[[#This Row],[Data]],"mm/aaaa") -> 01/2024 | D33: RESIDENCIAL CAMPO DE AVIAÇÃO - CONDOMINIO 14 BIS - BLOCO E - TORRE 09 | E33: Rua | F33: Campo de Pouso | G33: 193 | H33: Maranguape | I33: Paulista | J33: Residencial | K33: CR 002 PAULISTA | L33: 26227-7 | M33: Diafragma | N33: 44165 | O33: 47817 | P33: Argemiro / Marta | Q33: Gersom França Jr. | R33: Alex Rodrigues | S33: Ordinária
A34: 2024033 | B34: 45303 | C34: =TEXT(Fiscalizacoes[[#This Row],[Data]],"mm/aaaa") -> 01/2024 | D34: RESIDENCIAL CAMPO DE AVIAÇÃO - CONDOMINIO 14 BIS - BLOCO F - TORRE 10 | E34: Rua | F34: Campo de Pouso | G34: 193 | H34: Maranguape | I34: Paulista | J34: Residencial | K34: CR 002 PAULISTA | L34: 20703-9 | M34: Diafragma | N34: 42886 | O34: 46538 | P34: Argemiro / Marta | Q34: Gersom França Jr. | R34: Alex Rodrigues | S34: Ordinária
A35: 2024034 | B35: 45303 | C35: =TEXT(Fiscalizacoes[[#This Row],[Data]],"mm/aaaa") -> 01/2024 | D35: RESIDENCIAL CAMPO DE AVIAÇÃO - CONDOMINIO 14 BIS - BLOCO F - TORRE 11 | E35: Rua | F35: Campo de Pouso | G35: 193 | H35: Maranguape | I35: Paulista | J35: Residencial | K35: CR 002 PAULISTA | L35: 19295-3 | M35: Diafragma | N35: 42766 | O35: 46418 | P35: Argemiro / Marta | Q35: Gersom França Jr. | R35: Alex Rodrigues | S35: Ordinária
A36: 2024035 | B36: 45303 | C36: =TEXT(Fiscalizacoes[[#This Row],[Data]],"mm/aaaa") -> 01/2024 | D36: RESIDENCIAL CAMPO DE AVIAÇÃO - CONDOMINIO 14 BIS - BLOCO G - TORRE 12 | E36: Rua | F36: Campo de Pouso | G36: 193 | H36: Maranguape | I36: Paulista | J36: Residencial | K36: CR 002 PAULISTA | L36: 17914-0 | M36: Diafragma | N36: 42674 | O36: 46326 | P36: Argemiro / Marta | Q36: Gersom França Jr. | R36: Alex Rodrigues | S36: Ordinária
A37: 2024036 | B37: 45303 | C37: =TEXT(Fiscalizacoes[[#This Row],[Data]],"mm/aaaa") -> 01/2024 | D37: RESIDENCIAL CAMPO DE AVIAÇÃO - CONDOMINIO 14 BIS - BLOCO G - TORRE 13 | E37: Rua | F37: Campo de Pouso | G37: 193 | H37: Maranguape | I37: Paulista | J37: Residencial | K37: CR 002 PAULISTA | L37: 19962-6 | M37: Diafragma | N37: 42825 | O37: 46477 | P37: Argemiro / Marta | Q37: Gersom França Jr. | R37: Alex Rodrigues | S37: Ordinária
A38: 2024037 | B38: 45303 | C38: =TEXT(Fiscalizacoes[[#This Row],[Data]],"mm/aaaa") -> 01/2024 | D38: RESIDENCIAL CAMPO DE AVIAÇÃO - CONDOMINIO 14 BIS - BLOCO H - TORRE 14 | E38: Rua | F38: Campo de Pouso | G38: 193 | H38: Maranguape | I38: Paulista | J38: Residencial | K38: CR 002 PAULISTA | L38: 20655-5 | M38: Diafragma | N38: 42886 | O38: 46538 | P38: Argemiro / Marta | Q38: Gersom França Jr. | R38: Alex Rodrigues | S38: Ordinária
A39: 2024038 | B39: 45303 | C39: =TEXT(Fiscalizacoes[[#This Row],[Data]],"mm/aaaa") -> 01/2024 | D39: RESIDENCIAL CAMPO DE AVIAÇÃO - CONDOMINIO 14 BIS - BLOCO H - TORRE 15 | E39: Rua | F39: Campo de Pouso | G39: 193 | H39: Maranguape | I39: Paulista | J39: Residencial | K39: CR 002 PAULISTA | L39: 17574-6 | M39: Diafragma | N39: 42674 | O39: 46326 | P39: Argemiro / Marta | Q39: Gersom França Jr. | R39: Alex Rodrigues | S39: Ordinária
... A43: 2024042 | B43: 45303 | C43: =TEXT(Fiscalizacoes[[#This Row],[Data]],"mm/aaaa") -> 01/2024 | D43: RESIDENCIAL CAMPO DE AVIAÇÃO - CONDOMINIO 14 BIS - BLOCO J - TORRE 19 | E43: Rua | F43: Campo de Pouso | G43: 193 | H43: Maranguape | I43: Paulista | J43: Residencial | K43: CR 002 PAULISTA | L43: 24119-9 | M43: Diafragma | N43: 43616 | O43: 47269 | P43: Argemiro / Marta | Q43: Gersom França Jr. | R43: Alex Rodrigues | S43: Ordinária
A44: 2024043 | B44: 45303 | C44: =TEXT(Fiscalizacoes[[#This Row],[Data]],"mm/aaaa") -> 01/2024 | D44: RESIDENCIAL CAMPO DE AVIAÇÃO - CONDOMINIO SANTOS DUMONT - CR | E44: Rua | F44: Campo de Pouso | G44: 287 | H44: Maranguape | I44: Paulista | J44: Residencial | K44: CR 003 PAULISTA | L44: NA | M44: CR | P44: Argemiro / Marta | Q44: Gersom França Jr. | R44: Alex Rodrigues | S44: Ordinária
A45: 2024044 | B45: 45303 | C45: =TEXT(Fiscalizacoes[[#This Row],[Data]],"mm/aaaa") -> 01/2024 | D45: RESIDENCIAL CAMPO DE AVIAÇÃO - CONDOMINIO SANTOS DUMONT - BLOCO A - TORRE 01 | E45: Rua | F45: Campo de Pouso | G45: 287 | H45: Maranguape | I45: Paulista | J45: Residencial | K45: CR 003 PAULISTA | L45: 25014-7 | M45: Diafragma | N45: 43861 | O45: 47514 | P45: Argemiro / Marta | Q45: Gersom França Jr. | R45: Alex Rodrigues | S45: Ordinária
A46: 2024045 | B46: 45303 | C46: =TEXT(Fiscalizacoes[[#This Row],[Data]],"mm/aaaa") -> 01/2024 | D46: RESIDENCIAL CAMPO DE AVIAÇÃO - CONDOMINIO SANTOS DUMONT - BLOCO A - TORRE 02 | E46: Rua | F46: Campo de Pouso | G46: 287 | H46: Maranguape | I46: Paulista | J46: Residencial | K46: CR 003 PAULISTA | L46: 21021-8 | M46: Diafragma | N46: 43190 | O46: 46843 | P46: Argemiro / Marta | Q46: Gersom França Jr. | R46: Alex Rodrigues | S46: Ordinária
A47: 2024046 | B47: 45303 | C47: =TEXT(Fiscalizacoes[[#This Row],[Data]],"mm/aaaa") -> 01/2024 | D47: RESIDENCIAL CAMPO DE AVIAÇÃO - CONDOMINIO SANTOS DUMONT - BLOCO B - TORRE 03 | E47: Rua | F47: Campo de Pouso | G47: 287 | H47: Maranguape | I47: Paulista | J47: Residencial | K47: CR 003 PAULISTA | L47: 23073-4 | M47: Diafragma | N47: 43861 | O47: 47514 | P47: Argemiro / Marta | Q47: Gersom França Jr. | R47: Alex Rodrigues | S47: Ordinária
A48: 2024047 | B48: 45303 | C48: =TEXT(Fiscalizacoes[[#This Row],[Data]],"mm/aaaa") -> 01/2024 | D48: RESIDENCIAL CAMPO DE AVIAÇÃO - CONDOMINIO SANTOS DUMONT - SALÃO DE FESTAS | E48: Rua | F48: Campo de Pouso | G48: 287 | H48: Maranguape | I48: Paulista | J48: Residencial | K48: CR 003 PAULISTA | L48: 22474-0 | M48: Diafragma | N48: 43312 | O48: 46965 | P48: Argemiro / Marta | Q48: Gersom França Jr. | R48: Alex Rodrigues | S48: Ordinária
A49: 2024048 | B49: 45303 | C49: =TEXT(Fiscalizacoes[[#This Row],[Data]],"mm/aaaa") -> 01/2024 | D49: RESIDENCIAL CAMPO DE AVIAÇÃO - CONDOMINIO SANTOS DUMONT - BLOCO B - TORRE 04 | E49: Rua | F49: Campo de Pouso | G49: 287 | H49: Maranguape | I49: Paulista | J49: Residencial | K49: CR 003 PAULISTA | L49: 23914-3 | M49: Diafragma | N49: 43585 | O49: 47238 | P49: Argemiro / Marta | Q49: Gersom França Jr. | R49: Alex Rodrigues | S49: Ordinária
A50: 2024049 | B50: 45303 | C50: =TEXT(Fiscalizacoes[[#This Row],[Data]],"mm/aaaa") -> 01/2024 | D50: RESIDENCIAL CAMPO DE AVIAÇÃO - CONDOMINIO SANTOS DUMONT - BLOCO C - TORRE 05 | E50: Rua | F50: Campo de Pouso | G50: 287 | H50: Maranguape | I50: Paulista | J50: Residencial | K50: CR 003 PAULISTA | L50: 19360-7 | M50: Diafragma | N50: 42766 | O50: 46418 | P50: Argemiro / Marta | Q50: Gersom França Jr. | R50: Alex Rodrigues | S50: Ordinária
...

Sheet Nao_Conformidades
A1: Num_NC | B1: ID_FISC_original | C1: Detalhes_NC | D1: Equipamento | E1: Nao_conformidade | F1: Status_da_NC | G1: PARECER | H1: Data_parecer | I1: Rel_original | J1: Rel_checagem | K1: Cliente_NC | L1: ano | P1: ano | Q1: 2026
A2: 24001 | B2: 2024064 | C2: Manômetro de baixa com data de calibração vencida | D2: MANMT baixa | E2: Calibração vencida | F2: RESOLVIDA | G2: 02/2024 | H2: 45344 | I2: 01/2024 | K2: Cervejaria Debron Bier - Cervejaria Puma | L2: 2024
A3: 24002 | B3: 2024066 | C3: Manômetro de baixa com data de calibração vencida | D3: MANMT baixa | E3: Calibração vencida | F3: RESOLVIDA | G3: 02/2024 | H3: 45344 | I3: 01/2024 | K3: CJCM Petróleo Ltda - Posto Cempel Prazeres | L3: 2024 | P3: Rótulos de Linha | Q3: Contagem de Detalhes_NC | S3: nc | T3: qtde
A4: 24003 | B4: 2024066 | C4: Manômetro de alta com data de calibração vencida | D4: MANMT alta | E4: Calibração vencida | F4: RESOLVIDA | G4: 02/2024 | H4: 45344 | I4: 01/2024 | K4: CJCM Petróleo Ltda - Posto Cempel Prazeres | L4: 2024 | P4: Ausência de Etiqueta de calibração do medidor | Q4: 3 | S4: Ausência de Placa de identificação / segurança | T4: 7 | W4: 8 | X4: NÃO CONFORMIDADES MAIS FREQUENTES EM 2026
A5: 24004 | B5: 2024067 | C5: Manômetro de baixa com data de calibração vencida | D5: MANMT baixa | E5: Calibração vencida | F5: RESOLVIDA | G5: 02/2024 | H5: 45344 | I5: 01/2024 | K5: Tintas Iquine Ltda | L5: 2024 | P5: Ausência de Placa de identificação / segurança | Q5: 7 | W5: NÃO CONFORMIDADE | Y5: FREQÊNCIA | Z5: PERCENT
A6: 24005 | B6: 2024067 | C6: Manômetro de alta com data de calibração vencida | D6: MANMT alta | E6: Calibração vencida | F6: RESOLVIDA | G6: 02/2024 | H6: 45344 | I6: 01/2024 | K6: Tintas Iquine Ltda | L6: 2024 | P6: Cadeado oxidado impedindo a abertura da porta | Q6: 1 | W6: 1 | X6: Ausência de Placa de identificação / segurança | Y6: 7 | Z6: =(Y6/$Y$20)*100 -> 28
A7: 24006 | B7: 2024068 | C7: Manômetro de baixa com data de calibração vencida | D7: MANMT baixa | E7: Calibração vencida | F7: RESOLVIDA | G7: 02/2024 | H7: 45344 | I7: 01/2024 | K7: Perquimica - Pernambuco Quimica | L7: 2024 | P7: Entulho obstruindo o acesso | Q7: 1 | W7: 2 | X7: Lacre da válvula de bloqueio a montante violado | Y7: 3 | Z7: =(Y7/$Y$20)*100 -> 12
A8: 24007 | B8: 2024068 | C8: Manômetro de alta com data de calibração vencida | D8: MANMT alta | E8: Calibração vencida | F8: RESOLVIDA | G8: 02/2024 | H8: 45344 | I8: 01/2024 | K8: Perquimica - Pernambuco Quimica | L8: 2024 | P8: Etiqueta de calibração com data incompleta | Q8: 1 | W8: 3 | X8: Portão da estação desafixado | Y8: 3 | Z8: =(Y8/$Y$20)*100 -> 12
A9: 24008 | B9: 2024069 | C9: Manômetro de baixa com data de calibração vencida | D9: MANMT baixa | E9: Calibração vencida | F9: RESOLVIDA | G9: 05/2024 | H9: 45398 | I9: 02/2024 | K9: Boku's Pipocas e Salgados | L9: 2024 | P9: Lacre da válvula de bloqueio a montante violado | Q9: 3 | W9: 4 | X9: PSV com etiqueta de calibração vencida | Y9: 2 | Z9: =(Y9/$Y$20)*100 -> 8
A10: 24009 | B10: 2024096 | C10: Manômetro de baixa com data de calibração vencida | D10: MANMT baixa | E10: Calibração vencida | F10: RESOLVIDA | G10: 05/2024 | H10: 45398 | I10: 02/2024 | K10: ERP 378.5 - Bolsão Paulista 2 | L10: 2024 | P10: Placa de identificação / egurança ilegível | Q10: 1 | W10: 5 | X10: Ausência de Etiqueta de calibração do medidor | Y10: 1 | Z10: =(Y10/$Y$20)*100 -> 4
A11: 24010 | B11: 2024096 | C11: Manômetro de alta com data de calibração vencida | D11: MANMT alta | E11: Calibração vencida | F11: RESOLVIDA | G11: 05/2024 | H11: 45398 | I11: 02/2024 | K11: ERP 378.5 - Bolsão Paulista 2 | L11: 2024 | P11: Placa de identificação / segurança ilegível | Q11: 1 | W11: 6 | X11: Cadeado oxidado impedindo a abertura da porta | Y11: 1 | Z11: =(Y11/$Y$20)*100 -> 4
A12: 24011 | B12: 2024097 | C12: Manômetro de baixa com data de calibração vencida | D12: MANMT baixa | E12: Calibração vencida | F12: RESOLVIDA | G12: 05/2024 | H12: 45398 | I12: 02/2024 | K12: Posto Atlântida | L12: 2024 | P12: Portão da estação desafixado | Q12: 3 | W12: 7 | X12: Entulho obstruindo o acesso | Y12: 1 | Z12: =(Y12/$Y$20)*100 -> 4
A13: 24012 | B13: 2024130 | C13: Manômetro de baixa com data de calibração vencida | D13: MANMT baixa | E13: Calibração vencida | F13: RESOLVIDA | G13: 05/2024 | H13: 45398 | I13: 02/2024 | K13: ERP 378.3 | L13: 2024 | P13: PSV com etiqueta de calibração vencida | Q13: 2 | W13: 8 | X13: Etiqueta de calibração com data incompleta | Y13: 1 | Z13: =(Y13/$Y$20)*100 -> 4
A14: 24013 | B14: 2024130 | C14: Manômetro de alta com data de calibração vencida | D14: MANMT alta | E14: Calibração vencida | F14: RESOLVIDA | G14: 05/2024 | H14: 45398 | I14: 02/2024 | K14: ERP 378.3 | L14: 2024 | P14: PSV sem etiqueta de calibração | Q14: 1 | W14: 9 | X14: Placa de identificação / egurança ilegível | Y14: 1 | Z14: =(Y14/$Y$20)*100 -> 4
A15: 24014 | B15: 2024134 | C15: Manômetro de baixa com data de calibração vencida | D15: MANMT baixa | E15: Calibração vencida | F15: RESOLVIDA | G15: 05/2024 | H15: 45398 | I15: 02/2024 | K15: POSTO PERIMETRAL LTDA | L15: 2024 | P15: Quadro de medidores com a base oxidada | Q15: 1 | W15: 10 | X15: Placa de identificação / segurança ilegível | Y15: 1 | Z15: =(Y15/$Y$20)*100 -> 4
A16: 24015 | B16: 2024134 | C16: Manômetro de alta com data de calibração vencida | D16: MANMT alta | E16: Calibração vencida | F16: RESOLVIDA | G16: 05/2024 | H16: 45398 | I16: 02/2024 | K16: POSTO PERIMETRAL LTDA | L16: 2024 | P16: Quadro de medidores com a porta oxidada | Q16: 1 | W16: 11 | X16: PSV sem etiqueta de calibração | Y16: 1 | Z16: =(Y16/$Y$20)*100 -> 4
A17: 24016 | B17: 2024135 | C17: Válvula de segurança sem etiqueta de calibração | D17: PSV | E17: Ausência de etiqueta de calibração | F17: RESOLVIDA | G17: 05/2024 | H17: 45398 | I17: 02/2024 | K17: POSTO APM | L17: 2024 | P17: Vazamento de gás | Q17: 1 | W17: 12 | X17: Quadro de medidores com a base oxidada | Y17: 1 | Z17: =(Y17/$Y$20)*100 -> 4
A18: 24017 | B18: 2024139 | C18: Manômetro de baixa com data de calibração vencida | D18: MANMT baixa | E18: Calibração vencida | F18: RESOLVIDA | G18: 05/2024 | H18: 45398 | I18: 02/2024 | K18: ECOVIP COMÉRCIO DE COMBUSTÍVEIS LTDA | L18: 2024 | P18: Total Geral | Q18: 27 | W18: 13 | X18: Quadro de medidores com a porta oxidada | Y18: 1 | Z18: =(Y18/$Y$20)*100 -> 4
A19: 24018 | B19: 2024139 | C19: Manômetro de alta com data de calibração vencida | D19: MANMT alta | E19: Calibração vencida | F19: RESOLVIDA | G19: 05/2024 | H19: 45398 | I19: 02/2024 | K19: ECOVIP COMÉRCIO DE COMBUSTÍVEIS LTDA | L19: 2024 | W19: 14 | X19: Vazamento de gás | Y19: 1 | Z19: =(Y19/$Y$20)*100 -> 4
A20: 24019 | B20: 2024140 | C20: Manômetro de baixa com data de calibração vencida | D20: MANMT baixa | E20: Calibração vencida | F20: RESOLVIDA | G20: 05/2024 | H20: 45398 | I20: 02/2024 | K20: ERP 378.6 - BOLSÃO ABREU E LIMA | L20: 2024 | W20: total | Y20: =SUM(Y6:Y19) -> 25 | Z20: =(Y20/$Y$20)*100 -> 100
A21: 24020 | B21: 2024141 | C21: Manômetro de alta com data de calibração vencida | D21: MANMT alta | E21: Calibração vencida | F21: RESOLVIDA | G21: 05/2024 | H21: 45398 | I21: 02/2024 | K21: PROBENE FOODS | L21: 2024
A22: 24021 | B22: 2024145 | C22: Válvula de segurança sem etiqueta de calibração | D22: PSV | E22: Ausência de etiqueta de calibração | F22: RESOLVIDA | G22: 05/2024 | H22: 45398 | I22: 02/2024 | K22: ERP 402.3 - GRAVATÁ | L22: 2024
A23: 24022 | B23: 2024147 | C23: Vazamento de gás pelo piloto PCV | D23: PCV | E23: Vazamento de gás | F23: RESOLVIDA | G23: 05/2024 | H23: 45398 | I23: 02/2024 | K23: PIPOCAS GRAVATÁ (EX-NORDICAL E FGAL) | L23: 2024
A24: 24023 | B24: 2024269 | C24: Não se conseguiu o acesso à estação, pois, o trinco estava emperrado. | D24: ERP | E24: Impedimento do acesso | F24: RESOLVIDA | G24: 06/2024 | H24: 45448 | I24: 04/2024 | K24: ERP 422.8 - BOLSÃO BARRA DE JANGADA | L24: 2024
A25: 24024 | B25: 2024273 | C25: Cheiro forte dentro da central. Suspeita-se de vazamento | D25: CRM | E25: Suspeita de vazamento de gás | F25: RESOLVIDA | G25: 06/2024 | H25: 45448 | I25: 04/2024 | K25: EDIFÍCIO MENOTTI PRIORI - CRM | L25: 2024
A26: 24025 | B26: 2024284 | C26: Etiqueta de medição e calibração apagada | D26: CRM | E26: Etiqueta de calibração ilegível | F26: RESOLVIDA | G26: 06/2024 | H26: 45448 | I26: 04/2024 | K26: EDIFÍCIO MARINAS DA BARRA | L26: 2024
A27: 24026 | B27: 2024288 | C27: Etiqueta de medição e calibração ilegível devido a pintura por cima | D27: CRM | E27: Etiqueta de calibração ilegível | F27: RESOLVIDA | G27: 06/2024 | H27: 45448 | I27: 04/2024 | K27: EDIFÍCIO MONT BLANC | L27: 2024
A28: 24027 | B28: 2024295 | C28: Portão da estação quebrado. Trinco danificado | D28: CRM | E28: Portão da estação com defeito | F28: RESOLVIDA | G28: 06/2024 | H28: 45448 | I28: 04/2024 | K28: CAFÉ COM DENGO | L28: 2024
A29: 24028 | B29: 2024298 | C29: OPSO sem tampa | D29: OPSO | E29: OPSO sem tampa | F29: RESOLVIDA | G29: 06/2024 | H29: 45448 | I29: 04/2024 | K29: EDIFÍCIO GRAN PARC JAQUEIRA | L29: 2024
A30: 24029 | B30: 2024317 | C30: Estação de gás sem placa de identificação | D30: ERPM | E30: Ausência de placa de identificação | F30: RESOLVIDA | G30: 07/2024 | H30: 45499 | I30: 05/2024 | K30: FÁBRICA MARILAN | L30: 2024
A31: 24030 | B31: 2024320 | C31: Extintor com prazo de validade vencido | D31: ERPM | E31: Extintor com prazo de validade vencido | F31: RESOLVIDA | G31: 07/2024 | H31: 45499 | I31: 05/2024 | K31: PETROCAL PETRÓLEO CAVALCANTI LIMITADA | L31: 2024
A32: 24031 | B32: 2024321 | C32: Portão da CRM sem placa de identificação | D32: CRM | E32: Ausência de placa de identificação | F32: RESOLVIDA | G32: 07/2024 | H32: 45499 | I32: 05/2024 | K32: EDIFÍCIO JOSÉ PAES DE ANDRADE | L32: 2024
... A92: 25024 | B92: 2025237 | C92: Etiqueta do medidor vencida | D92: MVAZ | E92: Calibração vencida | F92: RESOLVIDA | G92: 70379331 | H92: 45860 | I92: 05/2025 | K92: RESIDENCIAL CLUBE VITA - QUALITÁ | L92: 2025
A93: 25025 | B93: 2025251 | C93: OPSO folgada | D93: OPSO | E93: OPSO com tampa solta | F93: RESOLVIDA | I93: 06/2025 | K93: EDIFICIO VILA VELHA COLONIAL | L93: 2025
A94: 25026 | B94: 2025252 | C94: Portão da estação com ausência da Placa de Segurança | D94: Placa de Segurança | E94: Ausência de placa de identificação | F94: RESOLVIDA | I94: 06/2025 | K94: EDIFICIO OLINDA COLONIAL | L94: 2025
A95: 25027 | B95: 2025263 | C95: OPSO folgada | D95: OPSO | E95: OPSO com tampa solta | F95: RESOLVIDA | I95: 06/2025 | K95: IACIL | L95: 2025
A96: 25028 | B96: 2025285 | C96: PSV com etiqueta de calibração vencida | D96: PSV | E96: PSV vencida | F96: RESOLVIDA | I96: 06/2025 | K96: TRAMONTINA DELTA S/A | L96: 2025
A97: 25029 | B97: 2025324 | C97: Estação de gás sem placa de identificação | D97: Placa de Segurança | E97: Ausência de placa de identificação | F97: RESOLVIDA | I97: 07/2025 | K97: AMBEV | L97: 2025
A98: 25030 | B98: 2025324 | C98: Estação de gás com mureta ao redor dificultando a passagem | D98: Estação | E98: Dificuladade de acesso | F98: RESOLVIDA | I98: 07/2025 | K98: AMBEV | L98: 2025
A99: 25031 | B99: 2025324 | C99: Cobertura da estação de gás com risco de desabamento devido a corrosão do material metálico presente | D99: Estação | E99: Risco de desabamento | F99: PENDENTE | I99: 07/2025 | K99: AMBEV | L99: 2025
...

Sheet Fiscalizacoes (2)
A1: Num da Fiscaliz | B1: Cliente | C1: Endereço 2 | D1: Status | E1: Logradouro | F1: Endereco | G1: Numero | H1: Bairro | I1: Cidade | J1: Nicho | K1: COD_CR | L1: Mvaz | M1: Tipo_Medidor | N1: Calibracao | O1: Prox_Calib | P1: Func_ARPE | Q1: Func_Copergas | R1: Motorista | S1: Tipo_fisc
A2: 107 | B2: RESIDENCIAL PRAIA DE JANGADA - CR | C2: =Fiscalizacoes7[[#This Row],[Logradouro]] &" "& Fiscalizacoes7[[#This Row],[Endereco]]&", " &Fiscalizacoes7[[#This Row],[Numero]] &", "&Fiscalizacoes7[[#This Row],[Bairro]] & " - "&Fiscalizacoes7[[#This Row],[Cidade]] -> Rua da Paz, 244, Barra de Jangada - Jaboatão dos Guararapes | D2: CONFORME | E2: Rua | F2: da Paz | G2: 244 | H2: Barra de Jangada | I2: Jaboatão dos Guararapes | J2: Residencial | K2: CR | L2: NA | M2: NA | N2: NA | O2: NA | P2: Marta | Q2: Paulo André de Oliveira | R2: Filipe Webster | S2: Ordinária
A3: 108 | B3: RESIDENCIAL PRAIA DE JANGADA - BLOCO 39 | C3: =Fiscalizacoes7[[#This Row],[Logradouro]] &" "& Fiscalizacoes7[[#This Row],[Endereco]]&", " &Fiscalizacoes7[[#This Row],[Numero]] &", "&Fiscalizacoes7[[#This Row],[Bairro]] & " - "&Fiscalizacoes7[[#This Row],[Cidade]] -> Rua da Paz, 244, Barra de Jangada - Jaboatão dos Guararapes | D3: CONFORME | E3: Rua | F3: da Paz | G3: 244 | H3: Barra de Jangada | I3: Jaboatão dos Guararapes | J3: Residencial | K3: CRM | L3: 17898-5 | M3: Diafragma | N3: 42674 | O3: 46326 | P3: Marta | Q3: Paulo André de Oliveira | R3: Filipe Webster | S3: Ordinária
A4: 109 | B4: RESIDENCIAL PRAIA DE JANGADA - BLOCO 41 | C4: =Fiscalizacoes7[[#This Row],[Logradouro]] &" "& Fiscalizacoes7[[#This Row],[Endereco]]&", " &Fiscalizacoes7[[#This Row],[Numero]] &", "&Fiscalizacoes7[[#This Row],[Bairro]] & " - "&Fiscalizacoes7[[#This Row],[Cidade]] -> Rua da Paz, 244, Barra de Jangada - Jaboatão dos Guararapes | D4: CONFORME | E4: Rua | F4: da Paz | G4: 244 | H4: Barra de Jangada | I4: Jaboatão dos Guararapes | J4: Residencial | K4: CRM | L4: 23900-3 | M4: Diafragma | N4: 43585 | O4: 47238 | P4: Marta | Q4: Paulo André de Oliveira | R4: Filipe Webster | S4: Ordinária
A5: 110 | B5: RESIDENCIAL PRAIA DE JANGADA - BLOCO 42 | C5: =Fiscalizacoes7[[#This Row],[Logradouro]] &" "& Fiscalizacoes7[[#This Row],[Endereco]]&", " &Fiscalizacoes7[[#This Row],[Numero]] &", "&Fiscalizacoes7[[#This Row],[Bairro]] & " - "&Fiscalizacoes7[[#This Row],[Cidade]] -> Rua da Paz, 244, Barra de Jangada - Jaboatão dos Guararapes | D5: CONFORME | E5: Rua | F5: da Paz | G5: 244 | H5: Barra de Jangada | I5: Jaboatão dos Guararapes | J5: Residencial | K5: CRM | L5: 17471-8 | M5: Diafragma | N5: 42674 | O5: 46326 | P5: Marta | Q5: Paulo André de Oliveira | R5: Filipe Webster | S5: Ordinária
A6: 111 | B6: RESIDENCIAL PRAIA DE JANGADA - BLOCO 35 | C6: =Fiscalizacoes7[[#This Row],[Logradouro]] &" "& Fiscalizacoes7[[#This Row],[Endereco]]&", " &Fiscalizacoes7[[#This Row],[Numero]] &", "&Fiscalizacoes7[[#This Row],[Bairro]] & " - "&Fiscalizacoes7[[#This Row],[Cidade]] -> Rua da Paz, 244, Barra de Jangada - Jaboatão dos Guararapes | D6: CONFORME | E6: Rua | F6: da Paz | G6: 244 | H6: Barra de Jangada | I6: Jaboatão dos Guararapes | J6: Residencial | K6: CRM | L6: 23035-9 | M6: Diafragma | N6: 43496 | O6: 47149 | P6: Marta | Q6: Paulo André de Oliveira | R6: Filipe Webster | S6: Ordinária
A7: 112 | B7: RESIDENCIAL PRAIA DE JANGADA - BLOCO 40 | C7: =Fiscalizacoes7[[#This Row],[Logradouro]] &" "& Fiscalizacoes7[[#This Row],[Endereco]]&", " &Fiscalizacoes7[[#This Row],[Numero]] &", "&Fiscalizacoes7[[#This Row],[Bairro]] & " - "&Fiscalizacoes7[[#This Row],[Cidade]] -> Rua da Paz, 244, Barra de Jangada - Jaboatão dos Guararapes | D7: CONFORME | E7: Rua | F7: da Paz | G7: 244 | H7: Barra de Jangada | I7: Jaboatão dos Guararapes | J7: Residencial | K7: CRM | L7: 19630-4 | M7: Diafragma | N7: 42825 | O7: 46477 | P7: Marta | Q7: Paulo André de Oliveira | R7: Filipe Webster | S7: Ordinária
A8: 113 | B8: RESIDENCIAL PRAIA DE JANGADA - BLOCO 37 | C8: =Fiscalizacoes7[[#This Row],[Logradouro]] &" "& Fiscalizacoes7[[#This Row],[Endereco]]&", " &Fiscalizacoes7[[#This Row],[Numero]] &", "&Fiscalizacoes7[[#This Row],[Bairro]] & " - "&Fiscalizacoes7[[#This Row],[Cidade]] -> Rua da Paz, 244, Barra de Jangada - Jaboatão dos Guararapes | D8: CONFORME | E8: Rua | F8: da Paz | G8: 244 | H8: Barra de Jangada | I8: Jaboatão dos Guararapes | J8: Residencial | K8: CRM | L8: 17970-1 | M8: Diafragma | N8: 42674 | O8: 46326 | P8: Marta | Q8: Paulo André de Oliveira | R8: Filipe Webster | S8: Ordinária
A9: 114 | B9: RESIDENCIAL PRAIA DE JANGADA - BLOCO 36 | C9: =Fiscalizacoes7[[#This Row],[Logradouro]] &" "& Fiscalizacoes7[[#This Row],[Endereco]]&", " &Fiscalizacoes7[[#This Row],[Numero]] &", "&Fiscalizacoes7[[#This Row],[Bairro]] & " - "&Fiscalizacoes7[[#This Row],[Cidade]] -> Rua da Paz, 244, Barra de Jangada - Jaboatão dos Guararapes | D9: CONFORME | E9: Rua | F9: da Paz | G9: 244 | H9: Barra de Jangada | I9: Jaboatão dos Guararapes | J9: Residencial | K9: CRM | L9: 17454-8 | M9: Diafragma | N9: 42674 | O9: 46326 | P9: Marta | Q9: Paulo André de Oliveira | R9: Filipe Webster | S9: Ordinária
A10: 115 | B10: RESIDENCIAL PRAIA DE JANGADA - BLOCO 33 | C10: =Fiscalizacoes7[[#This Row],[Logradouro]] &" "& Fiscalizacoes7[[#This Row],[Endereco]]&", " &Fiscalizacoes7[[#This Row],[Numero]] &", "&Fiscalizacoes7[[#This Row],[Bairro]] & " - "&Fiscalizacoes7[[#This Row],[Cidade]] -> Rua da Paz, 244, Barra de Jangada - Jaboatão dos Guararapes | D10: CONFORME | E10: Rua | F10: da Paz | G10: 244 | H10: Barra de Jangada | I10: Jaboatão dos Guararapes | J10: Residencial | K10: CRM | L10: 25513-8 | M10: Diafragma | N10: 43921 | O10: 47573 | P10: Marta | Q10: Paulo André de Oliveira | R10: Filipe Webster | S10: Ordinária
A11: 116 | B11: RESIDENCIAL PRAIA DE JANGADA - BLOCO 38 | C11: =Fiscalizacoes7[[#This Row],[Logradouro]] &" "& Fiscalizacoes7[[#This Row],[Endereco]]&", " &Fiscalizacoes7[[#This Row],[Numero]] &", "&Fiscalizacoes7[[#This Row],[Bairro]] & " - "&Fiscalizacoes7[[#This Row],[Cidade]] -> Rua da Paz, 244, Barra de Jangada - Jaboatão dos Guararapes | D11: CONFORME | E11: Rua | F11: da Paz | G11: 244 | H11: Barra de Jangada | I11: Jaboatão dos Guararapes | J11: Residencial | K11: CRM | L11: 17835-7 | M11: Diafragma | N11: 42674 | O11: 46326 | P11: Marta | Q11: Paulo André de Oliveira | R11: Filipe Webster | S11: Ordinária
A12: 117 | B12: RESIDENCIAL PRAIA DE JANGADA - BLOCO 31 | C12: =Fiscalizacoes7[[#This Row],[Logradouro]] &" "& Fiscalizacoes7[[#This Row],[Endereco]]&", " &Fiscalizacoes7[[#This Row],[Numero]] &", "&Fiscalizacoes7[[#This Row],[Bairro]] & " - "&Fiscalizacoes7[[#This Row],[Cidade]] -> Rua da Paz, 244, Barra de Jangada - Jaboatão dos Guararapes | D12: CONFORME | E12: Rua | F12: da Paz | G12: 244 | H12: Barra de Jangada | I12: Jaboatão dos Guararapes | J12: Residencial | K12: CRM | L12: 17549-8 | M12: Diafragma | N12: 42674 | O12: 46326 | P12: Marta | Q12: Paulo André de Oliveira | R12: Filipe Webster | S12: Ordinária
A13: 118 | B13: RESIDENCIAL PRAIA DE JANGADA - BLOCO 34 | C13: =Fiscalizacoes7[[#This Row],[Logradouro]] &" "& Fiscalizacoes7[[#This Row],[Endereco]]&", " &Fiscalizacoes7[[#This Row],[Numero]] &", "&Fiscalizacoes7[[#This Row],[Bairro]] & " - "&Fiscalizacoes7[[#This Row],[Cidade]] -> Rua da Paz, 244, Barra de Jangada - Jaboatão dos Guararapes | D13: CONFORME | E13: Rua | F13: da Paz | G13: 244 | H13: Barra de Jangada | I13: Jaboatão dos Guararapes | J13: Residencial | K13: CRM | L13: 20837-0 | M13: Diafragma | N13: 42886 | O13: 46538 | P13: Marta | Q13: Paulo André de Oliveira | R13: Filipe Webster | S13: Ordinária
A14: 119 | B14: RESIDENCIAL PRAIA DE JANGADA - BLOCO 32 | C14: =Fiscalizacoes7[[#This Row],[Logradouro]] &" "& Fiscalizacoes7[[#This Row],[Endereco]]&", " &Fiscalizacoes7[[#This Row],[Numero]] &", "&Fiscalizacoes7[[#This Row],[Bairro]] & " - "&Fiscalizacoes7[[#This Row],[Cidade]] -> Rua da Paz, 244, Barra de Jangada - Jaboatão dos Guararapes | D14: CONFORME | E14: Rua | F14: da Paz | G14: 244 | H14: Barra de Jangada | I14: Jaboatão dos Guararapes | J14: Residencial | K14: CRM | L14: 17780-6 | M14: Diafragma | N14: 42674 | O14: 46326 | P14: Marta | Q14: Paulo André de Oliveira | R14: Filipe Webster | S14: Ordinária
... A72: 177 | B72: RESIDENCIAL RENASCENÇA CANDEIAS - BLOCO 17 | C72: =Fiscalizacoes7[[#This Row],[Logradouro]] &" "& Fiscalizacoes7[[#This Row],[Endereco]]&", " &Fiscalizacoes7[[#This Row],[Numero]] &", "&Fiscalizacoes7[[#This Row],[Bairro]] & " - "&Fiscalizacoes7[[#This Row],[Cidade]] -> Rua Cárceres, 381, Candeias - Jaboatão dos Guararapes | D72: CONFORME | E72: Rua | F72: Cárceres | G72: 381 | H72: Candeias | I72: Jaboatão dos Guararapes | J72: Residencial | K72: CRM | L72: 17692-3 | M72: Diafragma | N72: 42674 | O72: 46326 | P72: Marta | Q72: Bruno Santos Assunção | R72: Filipe Webster | S72: Ordinária
A73: 178 | B73: RESIDENCIAL RENASCENÇA CANDEIAS - BLOCO - CR | C73: =Fiscalizacoes7[[#This Row],[Logradouro]] &" "& Fiscalizacoes7[[#This Row],[Endereco]]&", " &Fiscalizacoes7[[#This Row],[Numero]] &", "&Fiscalizacoes7[[#This Row],[Bairro]] & " - "&Fiscalizacoes7[[#This Row],[Cidade]] -> Rua Cárceres, 381, Candeias - Jaboatão dos Guararapes | D73: CONFORME | E73: Rua | F73: Cárceres | G73: 381 | H73: Candeias | I73: Jaboatão dos Guararapes | J73: Residencial | K73: CR | L73: NA | M73: NA | N73: NA | O73: NA | P73: Marta | Q73: Bruno Santos Assunção | R73: Filipe Webster | S73: Ordinária
A74: 179 | B74: MINOTTI PRIORI | C74: =Fiscalizacoes7[[#This Row],[Logradouro]] &" "& Fiscalizacoes7[[#This Row],[Endereco]]&", " &Fiscalizacoes7[[#This Row],[Numero]] &", "&Fiscalizacoes7[[#This Row],[Bairro]] & " - "&Fiscalizacoes7[[#This Row],[Cidade]] -> Praça Professor Fleming, 117, Jaqueira - Recife | D74: CONFORME | E74: Praça | F74: Professor Fleming | G74: 117 | H74: Jaqueira | I74: Recife | J74: Residencial | K74: Acesso impedido | L74: NA | M74: NA | N74: NA | O74: NA | P74: Marta | Q74: Bruno Santos Assunção | R74: Carlos Henrique | S74: Ordinária
A75: 180 | B75: CLARINDA PRIORI | C75: =Fiscalizacoes7[[#This Row],[Logradouro]] &" "& Fiscalizacoes7[[#This Row],[Endereco]]&", " &Fiscalizacoes7[[#This Row],[Numero]] &", "&Fiscalizacoes7[[#This Row],[Bairro]] & " - "&Fiscalizacoes7[[#This Row],[Cidade]] -> Praça Professor Fleming, 145, Jaqueira - Recife | D75: CONFORME | E75: Praça | F75: Professor Fleming | G75: 145 | H75: Jaqueira | I75: Recife | J75: Residencial | K75: CRM | L75: 24686-7 | M75: Diafragma | N75: 43496 | O75: 47149 | P75: Marta | Q75: Bruno Santos Assunção | R75: Carlos Henrique | S75: Ordinária
A76: 181 | B76: ILHA DE SANTO ALEIXO | C76: =Fiscalizacoes7[[#This Row],[Logradouro]] &" "& Fiscalizacoes7[[#This Row],[Endereco]]&", " &Fiscalizacoes7[[#This Row],[Numero]] &", "&Fiscalizacoes7[[#This Row],[Bairro]] & " - "&Fiscalizacoes7[[#This Row],[Cidade]] -> Praça Professor Fleming, 783, Jaqueira - Recife | D76: CONFORME | E76: Praça | F76: Professor Fleming | G76: 783 | H76: Jaqueira | I76: Recife | J76: Residencial | K76: CRM | L76: 24627-1 | M76: Diafragma | N76: 43616 | O76: 47269 | P76: Marta | Q76: Bruno Santos Assunção | R76: Carlos Henrique | S76: Ordinária
A77: 182 | B77: RIO AVE | C77: =Fiscalizacoes7[[#This Row],[Logradouro]] &" "& Fiscalizacoes7[[#This Row],[Endereco]]&", " &Fiscalizacoes7[[#This Row],[Numero]] &", "&Fiscalizacoes7[[#This Row],[Bairro]] & " - "&Fiscalizacoes7[[#This Row],[Cidade]] -> Rua Muniz Tavares, 115, Jaqueira - Recife | D77: CONFORME | E77: Rua | F77: Muniz Tavares | G77: 115 | H77: Jaqueira | I77: Recife | J77: Residencial | K77: CRM | L77: 25420-7 | M77: Diafragma | N77: 43951 | O77: 47603 | P77: Marta | Q77: Bruno Santos Assunção | R77: Carlos Henrique | S77: Ordinária
A78: 183 | B78: ITAIPAVA | C78: =Fiscalizacoes7[[#This Row],[Logradouro]] &" "& Fiscalizacoes7[[#This Row],[Endereco]]&", " &Fiscalizacoes7[[#This Row],[Numero]] &", "&Fiscalizacoes7[[#This Row],[Bairro]] & " - "&Fiscalizacoes7[[#This Row],[Cidade]] -> Rua Muniz Tavares, 147, Jaqueira - Recife | D78: CONFORME | E78: Rua | F78: Muniz Tavares | G78: 147 | H78: Jaqueira | I78: Recife | J78: Residencial | K78: CRM | L78: 33094 | M78: Diafragma | N78: 45565 | O78: 49217 | P78: Marta | Q78: Bruno Santos Assunção | R78: Carlos Henrique | S78: Ordinária
A79: 184 | B79: JARDINS DE CHRISTINA HARLEY LUNDGREN | C79: =Fiscalizacoes7[[#This Row],[Logradouro]] &" "& Fiscalizacoes7[[#This Row],[Endereco]]&", " &Fiscalizacoes7[[#This Row],[Numero]] &", "&Fiscalizacoes7[[#This Row],[Bairro]] & " - "&Fiscalizacoes7[[#This Row],[Cidade]] -> Rua Padre Roma, 291, Parnamirim - Recife | D79: NÃO CONFORME | E79: Rua | F79: Padre Roma | G79: 291 | H79: Parnamirim | I79: Recife | J79: Residencial | K79: CRM | L79: 32058-7 | M79: Diafragma | N79: 45382 | O79: 49034 | P79: Marta | Q79: Bruno Santos Assunção | R79: Carlos Henrique | S79: Ordinária
A80: 185 | B80: VIRGINIA | C80: =Fiscalizacoes7[[#This Row],[Logradouro]] &" "& Fiscalizacoes7[[#This Row],[Endereco]]&", " &Fiscalizacoes7[[#This Row],[Numero]] &", "&Fiscalizacoes7[[#This Row],[Bairro]] & " - "&Fiscalizacoes7[[#This Row],[Cidade]] -> Rua Muniz Tavares, 72, Jaqueira - Recife | D80: CONFORME | E80: Rua | F80: Muniz Tavares | G80: 72 | H80: Jaqueira | I80: Recife | J80: Residencial | K80: CRM | L80: 21842-1 | M80: Diafragma | N80: 43281 | O80: 46934 | P80: Marta | Q80: Bruno Santos Assunção | R80: Carlos Henrique | S80: Ordinária
A81: 186 | B81: SENHORZIN ESPETARIA E CHOPERIA | C81: =Fiscalizacoes7[[#This Row],[Logradouro]] &" "& Fiscalizacoes7[[#This Row],[Endereco]]&", " &Fiscalizacoes7[[#This Row],[Numero]] &", "&Fiscalizacoes7[[#This Row],[Bairro]] & " - "&Fiscalizacoes7[[#This Row],[Cidade]] -> Rua Sebastião Alves, 273, Tamarineira - Recife | D81: CONFORME | E81: Rua | F81: Sebastião Alves | G81: 273 | H81: Tamarineira | I81: Recife | J81: Comercial | K81: CRM | L81: 20175-8 | M81: Diafragma | N81: 42825 | O81: 46477 | P81: Marta | Q81: Bruno Santos Assunção | R81: Carlos Henrique | S81: Ordinária
A82: 187 | B82: MARIAZINHA BAR | C82: =Fiscalizacoes7[[#This Row],[Logradouro]] &" "& Fiscalizacoes7[[#This Row],[Endereco]]&", " &Fiscalizacoes7[[#This Row],[Numero]] &", "&Fiscalizacoes7[[#This Row],[Bairro]] & " - "&Fiscalizacoes7[[#This Row],[Cidade]] -> Rua Padre Roma, 246, Parnamirim - Recife | D82: CONFORME | E82: Rua | F82: Padre Roma | G82: 246 | H82: Parnamirim | I82: Recife | J82: Comercial | K82: CRM | L82: 29802-6 | M82: Diafragma | N82: 44804 | O82: 48457 | P82: Marta | Q82: Bruno Santos Assunção | R82: Carlos Henrique | S82: Ordinária
A83: 188 | B83: SÔNIA | C83: =Fiscalizacoes7[[#This Row],[Logradouro]] &" "& Fiscalizacoes7[[#This Row],[Endereco]]&", " &Fiscalizacoes7[[#This Row],[Numero]] &", "&Fiscalizacoes7[[#This Row],[Bairro]] & " - "&Fiscalizacoes7[[#This Row],[Cidade]] -> Rua Afonso Celso, 246, Tamarineira - Recife | D83: CONFORME | E83: Rua | F83: Afonso Celso | G83: 246 | H83: Tamarineira | I83: Recife | J83: Residencial | K83: CRM | L83: 24753-7 | M83: Diafragma | N83: 43708 | O83: 47361 | P83: Marta | Q83: Bruno Santos Assunção | R83: Carlos Henrique | S83: Ordinária
A84: 189 | B84: NIRÁ IZAKAYA | C84: =Fiscalizacoes7[[#This Row],[Logradouro]] &" "& Fiscalizacoes7[[#This Row],[Endereco]]&", " &Fiscalizacoes7[[#This Row],[Numero]] &", "&Fiscalizacoes7[[#This Row],[Bairro]] & " - "&Fiscalizacoes7[[#This Row],[Cidade]] -> Rua Afonso Celso, 203, Tamarineira - Recife | D84: CONFORME | E84: Rua | F84: Afonso Celso | G84: 203 | H84: Tamarineira | I84: Recife | J84: Comercial | K84: CRM | L84: 31816-7 | M84: Diafragma | N84: 45350 | O84: 49003 | P84: Marta | Q84: Bruno Santos Assunção | R84: Carlos Henrique | S84: Ordinária
A85: 190 | B85: CERVEJARIA DEBRON BIER - CERVEJARIA PUMA | C85: =Fiscalizacoes7[[#This Row],[Logradouro]] &" "& Fiscalizacoes7[[#This Row],[Endereco]]&", " &Fiscalizacoes7[[#This Row],[Numero]] &", "&Fiscalizacoes7[[#This Row],[Bairro]] & " - "&Fiscalizacoes7[[#This Row],[Cidade]] -> Estrada da Batalha, 1832, Jardim Jordão - Jaboatão dos Guararapes | D85: CONFORME | E85: Estrada | F85: da Batalha | G85: 1832 | H85: Jardim Jordão | I85: Jaboatão dos Guararapes | J85: Industrial | K85: ERPM | L85: 31463-3 | M85: Rotativo G 16 | N85: 45199 | O85: 47026 | P85: Argemiro / Marta | Q85: Bruno Santos Assunção | R85: Carlos Henrique | S85: Ordinária
A86: 191 | B86: BLU K CONFECÇÕES | C86: =Fiscalizacoes7[[#This Row],[Logradouro]] &" "& Fiscalizacoes7[[#This Row],[Endereco]]&", " &Fiscalizacoes7[[#This Row],[Numero]] &", "&Fiscalizacoes7[[#This Row],[Bairro]] & " - "&Fiscalizacoes7[[#This Row],[Cidade]] -> Rua Orlando Coelho da Silva, 31, Jardim Jordão - Jaboatão dos Guararapes | D86: CONFORME | E86: Rua | F86: Orlando Coelho da Silva | G86: 31 | H86: Jardim Jordão | I86: Jaboatão dos Guararapes | J86: Industrial | K86: ERPM | L86: 33522 | M86: Rotativo G 10 | N86: 45716 | O86: 47542 | P86: Argemiro / Marta | Q86: Bruno Santos Assunção | R86: Carlos Henrique | S86: Ordinária
A87: 192 | B87: CARAPITANGA INDÚSTRIA DE PESCADOS LTDA | C87: =Fiscalizacoes7[[#This Row],[Logradouro]] &" "& Fiscalizacoes7[[#This Row],[Endereco]]&", " &Fiscalizacoes7[[#This Row],[Numero]] &", "&Fiscalizacoes7[[#This Row],[Bairro]] & " - "&Fiscalizacoes7[[#This Row],[Cidade]] -> Rua José Alves Bezerra, 125, Prazeres - Jaboatão dos Guararapes | D87: CONFORME | E87: Rua | F87: José Alves Bezerra | G87: 125 | H87: Prazeres | I87: Jaboatão dos Guararapes | J87: Industrial | K87: ERPM | L87: 28973-6 | M87: Rotativo G 10 | N87: 44742 | O87: 46568 | P87: Argemiro / Marta | Q87: Bruno Santos Assunção | R87: Carlos Henrique | S87: Ordinária
A88: 193 | B88: CJCM PETRÓLEO LTDA SHELL - POSTO CEMOPEL PRAZERES | C88: =Fiscalizacoes7[[#This Row],[Logradouro]] &" "& Fiscalizacoes7[[#This Row],[Endereco]]&", " &Fiscalizacoes7[[#This Row],[Numero]] &", "&Fiscalizacoes7[[#This Row],[Bairro]] & " - "&Fiscalizacoes7[[#This Row],[Cidade]] -> Avenida Doutor Júlio Maranhão, 3062, Prazeres - Jaboatão dos Guararapes | D88: CONFORME | E88: Avenida | F88: Doutor Júlio Maranhão | G88: 3062 | H88: Prazeres | I88: Jaboatão dos Guararapes | J88: GNV | K88: ERPM | L88: 31789-6 | M88: Rotativo G 100 | N88: 45199 | O88: 30/092028 | P88: Argemiro / Marta | Q88: Bruno Santos Assunção | R88: Carlos Henrique | S88: Ordinária
A89: 194 | B89: TINTAS IQUINE LTDA | C89: =Fiscalizacoes7[[#This Row],[Logradouro]] &" "& Fiscalizacoes7[[#This Row],[Endereco]]&", " &Fiscalizacoes7[[#This Row],[Numero]] &", "&Fiscalizacoes7[[#This Row],[Bairro]] & " - "&Fiscalizacoes7[[#This Row],[Cidade]] -> Rua República Eslovaca, 325, Prazeres - Jaboatão dos Guararapes | D89: CONFORME | E89: Rua | F89: República Eslovaca | G89: 325 | H89: Prazeres | I89: Jaboatão dos Guararapes | J89: Industrial | K89: Morosidade | L89: NA | M89: NA | N89: NA | O89: NA | P89: Argemiro / Marta | Q89: Bruno Santos Assunção | R89: Carlos Henrique | S89: Ordinária
A90: 195 | B90: POSTO SUL LTDA - POSTO DE COMBUSTIVEIS PICHILAU | C90: =Fiscalizacoes7[[#This Row],[Logradouro]] &" "& Fiscalizacoes7[[#This Row],[Endereco]]&", " &Fiscalizacoes7[[#This Row],[Numero]] &", "&Fiscalizacoes7[[#This Row],[Bairro]] & " - "&Fiscalizacoes7[[#This Row],[Cidade]] -> Rodovia BR 101 Sul Km 83,7, , Prazeres - Jaboatão dos Guararapes | D90: CONFORME | E90: Rodovia | F90: BR 101 Sul Km 83,7 | H90: Prazeres | I90: Jaboatão dos Guararapes | J90: GNV | K90: ERPM | L90: 27813-0 | M90: Rotativo G 100 | N90: 45107 | O90: 46934 | P90: Argemiro / Marta | Q90: Bruno Santos Assunção | R90: Carlos Henrique | S90: Ordinária
AA1141: 535 | AB1141: EDF QUINTA DAS CAMÉLIAS | AC1141: =AF1141&" "&AG1141&", "&AH1141&", "&AI1141&", "&AJ1141 -> Rua Setúbal, 1058, Boa Viagem, Recife | AD1141: CONFORME | AF1141: Rua | AG1141: Setúbal | AH1141: 1058 | AI1141: Boa Viagem | AJ1141: Recife
AA1142: 536 | AB1142: EDF JOEL QUEIROZ | AC1142: =AF1142&" "&AG1142&", "&AH1142&", "&AI1142&", "&AJ1142 -> Avenida Boa Viagem, 5890, Boa Viagem, Recife | AD1142: CONFORME | AF1142: Avenida | AG1142: Boa Viagem | AH1142: 5890 | AI1142: Boa Viagem | AJ1142: Recife
AA1143: 537 | AB1143: EDF MARIA ANTÔNIA | AC1143: =AF1143&" "&AG1143&", "&AH1143&", "&AI1143&", "&AJ1143 -> Rua Setúbal, 1030, Boa Viagem, Recife | AD1143: CONFORME | AF1143: Rua | AG1143: Setúbal | AH1143: 1030 | AI1143: Boa Viagem | AJ1143: Recife
AA1144: 538 | AB1144: EDF ´PORTO ATLÂNTICO | AC1144: =AF1144&" "&AG1144&", "&AH1144&", "&AI1144&", "&AJ1144 -> Avenida Boa Viagem, 5822, Boa Viagem, Recife | AD1144: NÃO CONFORME | AF1144: Avenida | AG1144: Boa Viagem | AH1144: 5822 | AI1144: Boa Viagem | AJ1144: Recife
AA1145: 539 | AB1145: EDF RIO ARAGUAIA | AC1145: =AF1145&" "&AG1145&", "&AH1145&", "&AI1145&", "&AJ1145 -> Avenida Boa Viagem, 5802, Boa Viagem, Recife | AD1145: CONFORME | AF1145: Avenida | AG1145: Boa Viagem | AH1145: 5802 | AI1145: Boa Viagem | AJ1145: Recife
AA1146: 540 | AB1146: EDF QUAZAR | AC1146: =AF1146&" "&AG1146&", "&AH1146&", "&AI1146&", "&AJ1146 -> Rua Setúbal, 943, Boa Viagem, Recife | AD1146: CONFORME | AF1146: Rua | AG1146: Setúbal | AH1146: 943 | AI1146: Boa Viagem | AJ1146: Recife
AA1147: 541 | AB1147: EDF MARIA GLAUCIA | AC1147: =AF1147&" "&AG1147&", "&AH1147&", "&AI1147&", "&AJ1147 -> Rua Setúbal, 948, Boa Viagem, Recife | AD1147: NÃO FISCALIZADO | AF1147: Rua | AG1147: Setúbal | AH1147: 948 | AI1147: Boa Viagem | AJ1147: Recife
...

Sheet Gráficos 2026
B2: RESUMO DAS ATIVIDADES MENSAIS - GÁS NATURAL CANALIZADO - 2026
B4: META ANUAL: | D4: 384 | F4: REALIZADO: | H4: =P17 -> 530 | J4: % REAL/META: | L4: =(H4/D4)*100 -> 138.02083 | N4: META MENSAL: | Q4: =D4/12 -> 32
B6: 1 | C6: QUANTITATIVO DE FISCALIZAÇÕES REALIZADAS MENSALMENTE:
B8: SEGMENTO | D8: JAN | E8: FEV | F8: MAR | G8: ABR | H8: MAI | I8: JUN | J8: JUL | K8: AGO | L8: SET | M8: OUT | N8: NOV | O8: DEZ | P8: TOTAL | Q8: %
B9: Cogeração
B10: Comercial | D10: 6 | E10: 9 | F10: 3 | G10: 5 | H10: 16 | I10: 14 | J10: 3 | K10: 22 | L10: 3 | P10: =SUM(D10:O10) -> 81 | Q10: =(P10/$P$17)*100 -> 15.283019
B11: Encerrado
B12: ERP / CR | G12: 2 | H12: 8 | I12: 7 | L12: 1 | P12: =SUM(D12:O12) -> 18 | Q12: =(P12/$P$17)*100 -> 3.3962264
B13: ETC | L13: 2 | P13: =SUM(D13:O13) -> 2 | Q13: =(P13/$P$17)*100 -> 0.37735849
B14: GNV | F14: 2 | G14: 4 | H14: 12 | I14: 11 | L14: 2 | P14: =SUM(D14:O14) -> 31 | Q14: =(P14/$P$17)*100 -> 5.8490566
B15: Industrial | F15: 4 | G15: 4 | H15: 12 | I15: 17 | L15: 5 | P15: =SUM(D15:O15) -> 42 | Q15: =(P15/$P$17)*100 -> 7.9245283
B16: Residencial | D16: 62 | E16: 29 | F16: 80 | G16: 114 | H16: 35 | J16: 19 | K16: 14 | L16: 3 | P16: =SUM(D16:O16) -> 356 | Q16: =(P16/$P$17)*100 -> 67.169811
B17: Total | D17: =SUM(D9:D16) -> 68 | E17: =SUM(E9:E16) -> 38 | F17: =SUM(F9:F16) -> 89 | G17: =SUM(G9:G16) -> 129 | H17: =SUM(H9:H16) -> 83 | I17: =SUM(I9:I16) -> 49 | J17: 22 | K17: =SUM(K10:K16) -> 36 | L17: =SUM(L10:L16) -> 16 | P17: =SUM(P9:P16) -> 530 | Q17: =SUM(Q9:Q16) -> 100
C20: ACOMPANHAMENTO MENSAL DO QUANTITATIVO DE USUÁRIOS POR MUNÍCIPIO FISCALIZADOS EM 2026:
E22: JAN | F22: FEV | G22: MAR | H22: ABR | I22: MAI | J22: JUN | K22: JUL | L22: AGO | M22: SET | N22: OUT | O22: NOV | P22: DEZ | Q22: TOTAL
B23: Abreu e Lima | C23: Abreu e lima | J23: 3 | Q23: =SUM(E23:P23) -> 3
B24: Belo Jardim | J24: 8 | Q24: =SUM(E24:P24) -> 8 | AC24: Data | AD24: (Tudo)
B25: Camaragibe | I25: 36 | Q25: =SUM(E25:P25) -> 36
B26: Carpina | H26: 4 | Q26: =SUM(E26:P26) -> 4 | AC26: Rótulos de Linha | AD26: Contagem de ID_FISC
B27: Caruaru | I27: 14 | Q27: =SUM(E27:P27) -> 14 | AC27: Cogeração | AD27: 1 | AI27: Comercial | AJ27: 56 | AK27: =AJ27/$AJ$32 -> 0.11715481
B28: Cabo de Santo Agostinho | E28: 66 | Q28: =SUM(E28:P28) -> 66 | AC28: Comercial | AD28: 213 | AI28: ERP | AJ28: 17 | AK28: =AJ28/$AJ$32 -> 0.035564854
B29: Garanhuns | M29: 4 | Q29: =SUM(E29:P29) -> 4 | AC29: CR COM | AD29: 3 | AI29: GNV | AJ29: 29 | AK29: =AJ29/$AJ$32 -> 0.060669456
B30: Gloria do Goitá | I30: 1 | Q30: =SUM(E30:P30) -> 1 | AC30: CSC GNV | AD30: 1 | AI30: Industrial | AJ30: 37 | AK30: =AJ30/$AJ$32 -> 0.077405858
B31: Goiana | C31: Goiana | J31: 9 | Q31: =SUM(E31:P31) -> 9 | AC31: CSC Industrial | AD31: 1 | AI31: Residencial | AJ31: 339 | AK31: =AJ31/$AJ$32 -> 0.70920502
B32: Gravatá | I32: 3 | Q32: =SUM(E32:P32) -> 3 | AC32: ERP | AD32: 55 | AI32: total | AJ32: =SUM(AJ27:AJ31) -> 478 | AK32: =SUM(AK27:AK31) -> 1
B33: Igarassu | J33: 7 | Q33: =SUM(E33:P33) -> 7 | AC33: ETC | AD33: 15
B34: Ipojuca | J34: 15 | Q34: =SUM(E34:P34) -> 15 | AC34: GNV | AD34: 124
B35: Itapissuma | J35: 3 | Q35: =SUM(E35:P35) -> 3 | AC35: Industrial | AD35: 168
B36: Jaboatão dos Guararapes | E36: 2 | G36: 78 | Q36: =SUM(E36:P36) -> 80 | AC36: Residencial | AD36: 1138
B37: Moreno | I37: 4 | Q37: =SUM(E37:P37) -> 4 | AC37: (vazio)
B38: Nazaré da Mata | C38: Nazaré da Mata | H38: 4 | Q38: 4 | AC38: CR | AD38: 1
B39: Olinda | F39: 12 | Q39: =SUM(E39:P39) -> 12 | AC39: Total Geral | AD39: 1720
B40: Paudalho | H40: 1 | Q40: =SUM(E40:P40) -> 1
B41: Paulista | H41: 120 | Q41: =SUM(E41:P41) -> 120
B42: Petrolina | M42: 5 | Q42: =SUM(E42:P42) -> 5
B43: Pombos | I43: 3 | Q43: =SUM(E43:P43) -> 3
B44: Recife | F44: 26 | G44: 11 | K44: 22 | L44: 36 | M44: 5 | Q44: =SUM(E44:P44) -> 100
B45: São Caetano | J45: 2 | Q45: =SUM(E45:P45) -> 2
B46: São Lourenço da Mata | I46: 3 | Q46: =SUM(E46:P46) -> 3
B47: Tacaimbó | J47: 2 | Q47: =SUM(E47:P47) -> 2
...

Sheet Auxiliar
A1: ID Fiscalização | B1: Cliente | C1: Endereço | D1: Data | E1: N_relatorio | F1: ARPE | G1: Copergás
A2: =IF(Fiscalizacoes[[#This Row],[ID_FISC]]="","",Fiscalizacoes[[#This Row],[ID_FISC]]) -> 2024001 | B2: =IF(Fiscalizacoes[[#This Row],[Usuário]]="","",Fiscalizacoes[[#This Row],[Usuário]]) -> RESIDENCIAL CAMPO DE AVIAÇÃO - CONDOMINIO HANGAR - CR | C2: =CONCATENATE( Fiscalizacoes[[#This Row],[Logradouro]], " ", Fiscalizacoes[[#This Row],[Endereco]], ", ", Fiscalizacoes[[#This Row],[Numero]], ", ",Fiscalizacoes[[#This Row],[Bairro]], ", ",Fiscalizacoes[[#This Row],[Cidade]]) -> Rua Campo de Pouso, 97, Maranguape, Paulista | D2: =IF(Fiscalizacoes[[#This Row],[Data]]="","",Fiscalizacoes[[#This Row],[Data]]) -> 45303 | E2: =IF(Fiscalizacoes[[#This Row],[Mes_relatorio]]="","",Fiscalizacoes[[#This Row],[Mes_relatorio]]) -> 01/2024 | F2: =IF(Fiscalizacoes[[#This Row],[Func_ARPE]]="","",Fiscalizacoes[[#This Row],[Func_ARPE]]) -> Argemiro / Marta | G2: =IF(Fiscalizacoes[[#This Row],[Func_Copergas]]="","",Fiscalizacoes[[#This Row],[Func_Copergas]]) -> Gersom França Jr.
A3: =IF(Fiscalizacoes[[#This Row],[ID_FISC]]="","",Fiscalizacoes[[#This Row],[ID_FISC]]) -> 2024002 | B3: =IF(Fiscalizacoes[[#This Row],[Usuário]]="","",Fiscalizacoes[[#This Row],[Usuário]]) -> RESIDENCIAL CAMPO DE AVIAÇÃO - CONDOMINIO HANGAR - BLOCO A - TORRE 01 | C3: =CONCATENATE( Fiscalizacoes[[#This Row],[Logradouro]], " ", Fiscalizacoes[[#This Row],[Endereco]], ", ", Fiscalizacoes[[#This Row],[Numero]], ", ",Fiscalizacoes[[#This Row],[Bairro]], ", ",Fiscalizacoes[[#This Row],[Cidade]]) -> Rua Campo de Pouso, 97, Maranguape, Paulista | D3: =IF(Fiscalizacoes[[#This Row],[Data]]="","",Fiscalizacoes[[#This Row],[Data]]) -> 45303 | E3: =IF(Fiscalizacoes[[#This Row],[Mes_relatorio]]="","",Fiscalizacoes[[#This Row],[Mes_relatorio]]) -> 01/2024 | F3: =IF(Fiscalizacoes[[#This Row],[Func_ARPE]]="","",Fiscalizacoes[[#This Row],[Func_ARPE]]) -> Argemiro / Marta | G3: =IF(Fiscalizacoes[[#This Row],[Func_Copergas]]="","",Fiscalizacoes[[#This Row],[Func_Copergas]]) -> Gersom França Jr.
A4: =IF(Fiscalizacoes[[#This Row],[ID_FISC]]="","",Fiscalizacoes[[#This Row],[ID_FISC]]) -> 2024003 | B4: =IF(Fiscalizacoes[[#This Row],[Usuário]]="","",Fiscalizacoes[[#This Row],[Usuário]]) -> RESIDENCIAL CAMPO DE AVIAÇÃO - CONDOMINIO HANGAR - BLOCO A - TORRE 02 | C4: =CONCATENATE( Fiscalizacoes[[#This Row],[Logradouro]], " ", Fiscalizacoes[[#This Row],[Endereco]], ", ", Fiscalizacoes[[#This Row],[Numero]], ", ",Fiscalizacoes[[#This Row],[Bairro]], ", ",Fiscalizacoes[[#This Row],[Cidade]]) -> Rua Campo de Pouso, 97, Maranguape, Paulista | D4: =IF(Fiscalizacoes[[#This Row],[Data]]="","",Fiscalizacoes[[#This Row],[Data]]) -> 45303 | E4: =IF(Fiscalizacoes[[#This Row],[Mes_relatorio]]="","",Fiscalizacoes[[#This Row],[Mes_relatorio]]) -> 01/2024 | F4: =IF(Fiscalizacoes[[#This Row],[Func_ARPE]]="","",Fiscalizacoes[[#This Row],[Func_ARPE]]) -> Argemiro / Marta | G4: =IF(Fiscalizacoes[[#This Row],[Func_Copergas]]="","",Fiscalizacoes[[#This Row],[Func_Copergas]]) -> Gersom França Jr.
A5: =IF(Fiscalizacoes[[#This Row],[ID_FISC]]="","",Fiscalizacoes[[#This Row],[ID_FISC]]) -> 2024004 | B5: =IF(Fiscalizacoes[[#This Row],[Usuário]]="","",Fiscalizacoes[[#This Row],[Usuário]]) -> RESIDENCIAL CAMPO DE AVIAÇÃO - CONDOMINIO HANGAR - BLOCO B - TORRE 03 | C5: =CONCATENATE( Fiscalizacoes[[#This Row],[Logradouro]], " ", Fiscalizacoes[[#This Row],[Endereco]], ", ", Fiscalizacoes[[#This Row],[Numero]], ", ",Fiscalizacoes[[#This Row],[Bairro]], ", ",Fiscalizacoes[[#This Row],[Cidade]]) -> Rua Campo de Pouso, 97, Maranguape, Paulista | D5: =IF(Fiscalizacoes[[#This Row],[Data]]="","",Fiscalizacoes[[#This Row],[Data]]) -> 45303 | E5: =IF(Fiscalizacoes[[#This Row],[Mes_relatorio]]="","",Fiscalizacoes[[#This Row],[Mes_relatorio]]) -> 01/2024 | F5: =IF(Fiscalizacoes[[#This Row],[Func_ARPE]]="","",Fiscalizacoes[[#This Row],[Func_ARPE]]) -> Argemiro / Marta | G5: =IF(Fiscalizacoes[[#This Row],[Func_Copergas]]="","",Fiscalizacoes[[#This Row],[Func_Copergas]]) -> Gersom França Jr.
